<?xml version="1.0"?>
<robot xmlns:xacro="http://www.ros.org/wiki/xacro" name="car">

    <!--
            To generate the correct .URDF from this XACRO file see
    https://answers.ros.org/question/10401/how-to-convert-xacro-file-to-urdf-file/
    -->

    <!--CONSTANTS-->
    <xacro:property name="PI" value="3.14159" />

    <!-- Load car properties from YAML, compute moments if inertia based on masses -->
    <xacro:property name="yaml_file" value="$(find line_tracking_race)/config/car_properties.yaml" />
    <xacro:property name="p" value="${xacro.load_yaml(yaml_file)}" />

    <xacro:property name="BOX_IXX"
        value="${p['BOX_MASS'] * (p['BOX_LY'] * p['BOX_LY'] + p['BOX_LZ'] * p['BOX_LZ']) / 12.0}" />
    <xacro:property name="BOX_IYY"
        value="${p['BOX_MASS'] * (p['BOX_LX'] * p['BOX_LX'] + p['BOX_LZ'] * p['BOX_LZ']) / 12.0}" />
    <xacro:property name="BOX_IZZ"
        value="${p['BOX_MASS'] * (p['BOX_LX'] * p['BOX_LX'] + p['BOX_LY'] * p['BOX_LY']) / 12.0}" />

    <xacro:property name="WHEEL_IXX"
        value="${p['WHEEL_MASS']*(3*p['WHEEL_R']*p['WHEEL_R'] + p['WHEEL_L']*p['WHEEL_L'])/12.0}" />
    <xacro:property name="WHEEL_IYY"
        value="${p['WHEEL_MASS']*(3*p['WHEEL_R']*p['WHEEL_R'] + p['WHEEL_L']*p['WHEEL_L'])/12.0}" />
    <xacro:property name="WHEEL_IZZ" value="${0.5*p['WHEEL_MASS']*p['WHEEL_R']*p['WHEEL_R']}" />

    <!--###########
    COLORS used for the links. Only in RViz, for Gazebo is different ###########-->

    <material name="box_material">
        <color rgba="1 0.15 0.08 0.3" />
    </material>
    <material name="wheel_material">
        <color rgba="0.26 0.27 0.3 1.0" />
    </material>
    <material name="camera_material">
        <color rgba="1 0.7 0.3 1.0" />
    </material>

    <!-- Gazebo plugins -->
    <gazebo>
        <plugin name="gazebo_ros_control" filename="libgazebo_ros_control.so">
            <robotNamespace>/car</robotNamespace>
            <!-- <robotSimType>gazebo_ros_control/DefaultRobotHWSim</robotSimType> -->
        </plugin>
    </gazebo>

    <!--###########
    MACRO for links and joints ###########-->

    <xacro:macro name="wheel_macro" params="n parent x y z actuated">
        <link name="wheel_${n}">
            <inertial>
                <origin xyz="0 0 0" rpy="0 0 0" />
                <mass value="${p['WHEEL_MASS']}" />
                <inertia ixx="${WHEEL_IXX}" ixy="0" ixz="0" iyy="${WHEEL_IYY}" iyz="0"
                    izz="${WHEEL_IZZ}" />
            </inertial>
            <visual>
                <origin xyz="0 0 0" rpy="0 0 0" />
                <geometry>
                    <cylinder radius="${p['WHEEL_R']}" length="${p['WHEEL_L']}" />
                </geometry>
                <material name="wheel_material" />
            </visual>
            <collision>
                <origin xyz="0 0 0" rpy="0 0 0" />
                <geometry>
                    <cylinder radius="${p['WHEEL_R']}" length="${p['WHEEL_L']}" />
                </geometry>
                <!-- Contact coeffienct not needed, for Gazebo the material properties are defined
                separately in this file -->
                <!-- <contact_coefficients mu="${p['WHEEL_MU']}" kp="${p['WHEEL_KP']}"
                    kd="${p['WHEEL_KD']}" /> -->
            </collision>
        </link>
        <joint name="axle_${n}" type="continuous">
            <origin xyz="${x} ${y} ${z}" rpy="${-PI/2} 0 0" />
            <axis xyz="0 0 1" />
            <parent link="${parent}" />
            <child link="wheel_${n}" />
            <dynamics damping="${p['JOINT_DAMPING']}" friction="${p['JOINT_FRICTION']}" />
            <limit effort="${p['JOINT_MAX_EFFORT']}" velocity="${p['JOINT_MAX_SPEED']}" />
        </joint>
        <xacro:if value="${actuated}">
            <transmission name="trans_${n}">
                <type>transmission_interface/SimpleTransmission</type>
                <joint name="axle_${n}">
                    <hardwareInterface>hardware_interface/VelocityJointInterface</hardwareInterface>
                    <!-- <hardwareInterface>EffortJointInterface</hardwareInterface> -->
                </joint>
                <actuator name="${n}_motor">
                    <hardwareInterface>hardware_interface/VelocityJointInterface</hardwareInterface>
                    <!-- <hardwareInterface>EffortJointInterface</hardwareInterface> -->
                    <mechanicalReduction>1</mechanicalReduction>
                </actuator>
            </transmission>
        </xacro:if>

        <gazebo reference="wheel_${n}">
            <material>Gazebo/DarkGrey </material>
            <mu1 value="${p['WHEEL_MU1']}" />
            <mu2 value="${p['WHEEL_MU2']}" />
            <kp value="${p['WHEEL_KD']}" />
            <kd value="${p['WHEEL_KP']}" />
        </gazebo>

    </xacro:macro>

    <!-- ########### MODEL LINKS AND JOINTS ########### -->

    <link name="chassis">
        <inertial>
            <origin xyz="0 0 0" rpy="0 0 0" />
            <mass value="${p['BOX_MASS']}" />
            <inertia ixx="${BOX_IXX}" ixy="0" ixz="0"
                iyy="${BOX_IYY}" iyz="0"
                izz="${BOX_IZZ}" />
        </inertial>
        <visual>
            <origin xyz="0 0 0" rpy="0 0 0" />
            <geometry>
                <box size="${p['BOX_LX']} ${p['BOX_LY']} ${p['BOX_LZ']}" />
            </geometry>
            <material name="box_material" />
        </visual>
        <collision>
            <origin xyz="0 0 0" rpy="0 0 0" />
            <geometry>
                <box size="${p['BOX_LX']} ${p['BOX_LY']} ${p['BOX_LZ']}" />
            </geometry>
        </collision>
    </link>

    <gazebo reference="chassis">
        <material>Gazebo/RedTransparent</material>
    </gazebo>

    <!-- Dummy link with null inertia for KDL -->
    <link name="dummy" />
    <joint name="dummy_to_chassis" type="fixed">
        <parent link="dummy" />
        <child link="chassis" />
    </joint>

    <!-- Frontal axle able to rotate, to which the front wheels will be connected -->
    <link name="front_axle">
        <inertial>
            <origin xyz="0 0 0" rpy="${-PI/2} 0 0" />
            <mass value="${p['BOX_MASS']}" />
            <inertia ixx="${BOX_IXX}" ixy="0" ixz="0"
                iyy="${BOX_IYY}" iyz="0"
                izz="${BOX_IZZ}" />
        </inertial>
        <visual>
            <origin xyz="0 0 0" rpy="${-PI/2} 0 0" />
            <geometry>
                <cylinder radius="0.06" length="${p['BOX_LY']}" />
            </geometry>
            <material name="camera_material" />
        </visual>
        <collision>
            <origin xyz="0 0 0" rpy="${-PI/2} 0 0" />
            <geometry>
                <cylinder radius="0.05" length="${p['BOX_LY']}" />
            </geometry>
        </collision>
    </link>
    <gazebo reference="front_axle">
        <material>Gazebo/YellowGlow</material>
    </gazebo>
    <!-- Joint connecting the front axle to the  chassis. This joint is not controlled.-->
    <joint name="steer_front" type="revolute">
        <origin xyz="${p['BOX_LX']/2} 0 ${-p['BOX_LZ']/2}" rpy="0 0 0" />
        <axis xyz="0 0 1" />
        <parent link="chassis" />
        <child link="front_axle" />
        <dynamics damping="${p['JOINT_DAMPING']}" friction="${p['JOINT_FRICTION']}" />
        <limit effort="${p['JOINT_MAX_EFFORT']}" velocity="${p['JOINT_MAX_SPEED']}"
            upper="${2 * PI * p['STEER_FRONT_LIMIT']/360}"
            lower="${-2 * PI * p['STEER_FRONT_LIMIT']/360}" />
    </joint>


    <!-- Add wheels, only the front one are actuated -->

    <xacro:wheel_macro n="front_left" parent="front_axle" x="0" y="${p['BOX_LY']/2}" z="0"
        actuated="true" />

    <xacro:wheel_macro n="front_right" parent="front_axle" x="0" y="${-p['BOX_LY']/2}" z="0"
        actuated="true" />

    <xacro:wheel_macro n="back_left" parent="chassis" x="${-p['BOX_LX']/2}"
        y="${p['BOX_LY']/2}" z="${-p['BOX_LZ']/2}" actuated="false" />

    <xacro:wheel_macro n="back_right" parent="chassis" x="${-p['BOX_LX']/2}"
        y="${-p['BOX_LY']/2}" z="${-p['BOX_LZ']/2}" actuated="false" />

    <!-- Camera -->
    <link name="camera_link">
        <visual>
            <geometry>
                <box size="0.04 0.08 0.08" />
            </geometry>
            <material name="camera_material" />
        </visual>
    </link>

    <!-- Camera is rigidly attached to the front axle, not the chassis, but placed above the chassis -->
    <joint name="camera_joint" type="fixed">
        <parent link="front_axle" />
        <child link="camera_link" />
        <origin xyz="0.02 0 ${p['BOX_LZ'] + 0.02}" rpy="0 ${PI/6} 0" />
    </joint>

    <!-- Image Frame -->
    <link name="camera_link_optical"></link>

    <joint name="camera_optical_joint" type="fixed">
        <origin xyz="0 0 0" rpy="${-PI/2} ${PI/2} 0" />
        <parent link="camera_link" />
        <child link="camera_link_optical" />
    </joint>

    <gazebo reference="camera_link">
        <sensor name="front_camera" type="camera">
            <robotNamespace>/car</robotNamespace>
            <pose> 0 0 0 0 0 0 </pose>
            <visualize>true</visualize>
            <update_rate>10</update_rate>
            <camera>
                <horizontal_fov>2.0</horizontal_fov>
                <image>
                    <format>R8G8B8</format>
                    <width>640</width>
                    <height>480</height>
                </image>
                <clip>
                    <near>0.05</near>
                    <far>8.0</far>
                </clip>
            </camera>
            <plugin name="camera_controller" filename="libgazebo_ros_camera.so">
                <robotNamespace>/car</robotNamespace>
                <frame_name>camera_link_optical</frame_name>
            </plugin>
        </sensor>
    </gazebo>

</robot>