<?xml version="1.0" ?>
<!-- =================================================================================== -->
<!-- |    This document was autogenerated by xacro from /home/roscourse/catkin_ws/src/line_tracking_race/resources/urdf/car.xacro | -->
<!-- |    EDITING THIS FILE BY HAND IS NOT RECOMMENDED                                 | -->
<!-- =================================================================================== -->
<robot name="car">
  <!--
            To generate the correct .URDF from this XACRO file see https://answers.ros.org/question/10401/how-to-convert-xacro-file-to-urdf-file/
    -->
  <!--########### COLORS used for the links ###########-->
  <!--colors are currently implemented as macro because just defining them, as shown in the ROS tutorial, seems not to work-->
  <material name="box_material">
    <color rgba="1 0.15 0.08 0.3"/>
  </material>
  <material name="wheel_material">
    <color rgba="0.26 0.27 0.3 1.0"/>
  </material>
  <material name="camera_material">
    <color rgba="1 0.7 0.3 1.0"/>
  </material>
  <!--########### MACRO for links and joints ###########-->
  <!-- ########### MODEL LINKS AND JOINTS ########### -->
  <link name="chassis">
    <inertial>
      <origin rpy="0 0 0" xyz="0 0 0"/>
      <mass value="0.5"/>
      <inertia ixx="0.01875" ixy="0" ixz="0" iyy="0.04541666666666667" iyz="0" izz="0.056666666666666664"/>
    </inertial>
    <visual>
      <origin rpy="0 0 0" xyz="0 0 0"/>
      <geometry>
        <box size="1.0 0.6 0.3"/>
      </geometry>
      <material name="box_material"/>
    </visual>
    <collision>
      <origin rpy="0 0 0" xyz="0 0 0"/>
      <geometry>
        <box size="1.0 0.6 0.3"/>
      </geometry>
    </collision>
  </link>
  <gazebo reference="chassis">
    <material>Gazebo/RedBright </material>
  </gazebo>
  <link name="base_link"/>
  <joint name="base_link_to_chassis" type="fixed">
    <parent link="base_link"/>
    <child link="chassis"/>
  </joint>
  <link name="wheel_front_left">
    <inertial>
      <origin rpy="0 0 0" xyz="0 0 0"/>
      <mass value="0.05"/>
      <inertia ixx="0.0009479166666666668" ixy="0" ixz="0" iyy="0.0009479166666666668" iyz="0" izz="0.0015625"/>
    </inertial>
    <visual>
      <origin rpy="0 0 0" xyz="0 0 0"/>
      <geometry>
        <cylinder length="0.2" radius="0.25"/>
      </geometry>
      <material name="wheel_material"/>
    </visual>
    <collision>
      <origin rpy="0 0 0" xyz="0 0 0"/>
      <geometry>
        <cylinder length="0.2" radius="0.25"/>
      </geometry>
    </collision>
  </link>
  <joint name="axel_front_left" type="continuous">
    <origin rpy="-1.570795 0 0" xyz="0.4 0.3 -0.15"/>
    <axis xyz="0 0 1"/>
    <parent link="chassis"/>
    <child link="wheel_front_left"/>
    <dynamics damping="0.01" friction="0.01"/>
    <limit effort="50.0" velocity="50.0"/>
  </joint>
  <transmission name="trans_front_left">
    <type>transmission_interface/SimpleTransmission</type>
    <joint name="axel_front_left">
      <hardwareInterface>hardware_interface/EffortJointInterface</hardwareInterface>
    </joint>
    <actuator name="front_left_motor">
      <mechanicalReduction>1</mechanicalReduction>
      <hardwareInterface>hardware_interface/EffortJointInterface</hardwareInterface>
    </actuator>
  </transmission>
  <gazebo reference="wheel_front_left">
    <material>Gazebo/DarkGrey  </material>
  </gazebo>
  <link name="wheel_front_right">
    <inertial>
      <origin rpy="0 0 0" xyz="0 0 0"/>
      <mass value="0.05"/>
      <inertia ixx="0.0009479166666666668" ixy="0" ixz="0" iyy="0.0009479166666666668" iyz="0" izz="0.0015625"/>
    </inertial>
    <visual>
      <origin rpy="0 0 0" xyz="0 0 0"/>
      <geometry>
        <cylinder length="0.2" radius="0.25"/>
      </geometry>
      <material name="wheel_material"/>
    </visual>
    <collision>
      <origin rpy="0 0 0" xyz="0 0 0"/>
      <geometry>
        <cylinder length="0.2" radius="0.25"/>
      </geometry>
    </collision>
  </link>
  <joint name="axel_front_right" type="continuous">
    <origin rpy="-1.570795 0 0" xyz="0.4 -0.3 -0.15"/>
    <axis xyz="0 0 1"/>
    <parent link="chassis"/>
    <child link="wheel_front_right"/>
    <dynamics damping="0.01" friction="0.01"/>
    <limit effort="50.0" velocity="50.0"/>
  </joint>
  <transmission name="trans_front_right">
    <type>transmission_interface/SimpleTransmission</type>
    <joint name="axel_front_right">
      <hardwareInterface>hardware_interface/EffortJointInterface</hardwareInterface>
    </joint>
    <actuator name="front_right_motor">
      <mechanicalReduction>1</mechanicalReduction>
      <hardwareInterface>hardware_interface/EffortJointInterface</hardwareInterface>
    </actuator>
  </transmission>
  <gazebo reference="wheel_front_right">
    <material>Gazebo/DarkGrey  </material>
  </gazebo>
  <link name="wheel_back_left">
    <inertial>
      <origin rpy="0 0 0" xyz="0 0 0"/>
      <mass value="0.05"/>
      <inertia ixx="0.0009479166666666668" ixy="0" ixz="0" iyy="0.0009479166666666668" iyz="0" izz="0.0015625"/>
    </inertial>
    <visual>
      <origin rpy="0 0 0" xyz="0 0 0"/>
      <geometry>
        <cylinder length="0.2" radius="0.25"/>
      </geometry>
      <material name="wheel_material"/>
    </visual>
    <collision>
      <origin rpy="0 0 0" xyz="0 0 0"/>
      <geometry>
        <cylinder length="0.2" radius="0.25"/>
      </geometry>
    </collision>
  </link>
  <joint name="axel_back_left" type="continuous">
    <origin rpy="-1.570795 0 0" xyz="-0.4 0.3 -0.15"/>
    <axis xyz="0 0 1"/>
    <parent link="chassis"/>
    <child link="wheel_back_left"/>
    <dynamics damping="0.01" friction="0.01"/>
    <limit effort="50.0" velocity="50.0"/>
  </joint>
  <transmission name="trans_back_left">
    <type>transmission_interface/SimpleTransmission</type>
    <joint name="axel_back_left">
      <hardwareInterface>hardware_interface/EffortJointInterface</hardwareInterface>
    </joint>
    <actuator name="back_left_motor">
      <mechanicalReduction>1</mechanicalReduction>
      <hardwareInterface>hardware_interface/EffortJointInterface</hardwareInterface>
    </actuator>
  </transmission>
  <gazebo reference="wheel_back_left">
    <material>Gazebo/DarkGrey  </material>
  </gazebo>
  <link name="wheel_back_right">
    <inertial>
      <origin rpy="0 0 0" xyz="0 0 0"/>
      <mass value="0.05"/>
      <inertia ixx="0.0009479166666666668" ixy="0" ixz="0" iyy="0.0009479166666666668" iyz="0" izz="0.0015625"/>
    </inertial>
    <visual>
      <origin rpy="0 0 0" xyz="0 0 0"/>
      <geometry>
        <cylinder length="0.2" radius="0.25"/>
      </geometry>
      <material name="wheel_material"/>
    </visual>
    <collision>
      <origin rpy="0 0 0" xyz="0 0 0"/>
      <geometry>
        <cylinder length="0.2" radius="0.25"/>
      </geometry>
    </collision>
  </link>
  <joint name="axel_back_right" type="continuous">
    <origin rpy="-1.570795 0 0" xyz="-0.4 -0.3 -0.15"/>
    <axis xyz="0 0 1"/>
    <parent link="chassis"/>
    <child link="wheel_back_right"/>
    <dynamics damping="0.01" friction="0.01"/>
    <limit effort="50.0" velocity="50.0"/>
  </joint>
  <transmission name="trans_back_right">
    <type>transmission_interface/SimpleTransmission</type>
    <joint name="axel_back_right">
      <hardwareInterface>hardware_interface/EffortJointInterface</hardwareInterface>
    </joint>
    <actuator name="back_right_motor">
      <mechanicalReduction>1</mechanicalReduction>
      <hardwareInterface>hardware_interface/EffortJointInterface</hardwareInterface>
    </actuator>
  </transmission>
  <gazebo reference="wheel_back_right">
    <material>Gazebo/DarkGrey  </material>
  </gazebo>
  <!-- Camera -->
  <link name="camera_link">
    <visual>
      <geometry>
        <box size="0.04 0.08 0.08"/>
      </geometry>
      <material name="camera_material"/>
    </visual>
  </link>
  <joint name="camera_joint" type="fixed">
    <parent link="chassis"/>
    <child link="camera_link"/>
    <origin rpy="0 0.5235983333333333 0" xyz="0.52 0 0.15"/>
  </joint>
  <!-- Image Frame -->
  <link name="camera_link_optical"/>
  <joint name="camera_optical_joint" type="fixed">
    <origin rpy="-1.570795 1.570795 0" xyz="0 0 0"/>
    <parent link="camera_link"/>
    <child link="camera_link_optical"/>
  </joint>
  <gazebo reference="camera_link">
    <plugin filename="libgazebo_ros_control.so" name="gazebo_ros_control">
      <robotNamespace>/car</robotNamespace>
    </plugin>
    <sensor name="camera" type="camera">
      <pose> 0 0 0 0 0 0 </pose>
      <visualize>true</visualize>
      <update_rate>10</update_rate>
      <camera>
        <horizontal_fov>5.0</horizontal_fov>
        <image>
          <format>R8G8B8</format>
          <width>640</width>
          <height>480</height>
        </image>
        <clip>
          <near>0.05</near>
          <far>8.0</far>
        </clip>
      </camera>
      <plugin filename="libgazebo_ros_camera.so" name="camera_controller">
        <frame_name>camera_link_optical</frame_name>
      </plugin>
    </sensor>
  </gazebo>
</robot>

